Traceback (most recent call last):
  File "C:\Users\tirab\AppData\Local\Programs\Python\Python310\lib\site-packages\jupyter_cache\executors\utils.py", line 58, in single_nb_execution
    executenb(
  File "C:\Users\tirab\AppData\Local\Programs\Python\Python310\lib\site-packages\nbclient\client.py", line 1314, in execute
    return NotebookClient(nb=nb, resources=resources, km=km, **kwargs).execute()
  File "C:\Users\tirab\AppData\Roaming\Python\Python310\site-packages\jupyter_core\utils\__init__.py", line 173, in wrapped
    return loop.run_until_complete(inner)
  File "C:\Users\tirab\AppData\Local\Programs\Python\Python310\lib\asyncio\base_events.py", line 646, in run_until_complete
    return future.result()
  File "C:\Users\tirab\AppData\Local\Programs\Python\Python310\lib\site-packages\nbclient\client.py", line 709, in async_execute
    await self.async_execute_cell(
  File "C:\Users\tirab\AppData\Local\Programs\Python\Python310\lib\site-packages\nbclient\client.py", line 1062, in async_execute_cell
    await self._check_raise_for_error(cell, cell_index, exec_reply)
  File "C:\Users\tirab\AppData\Local\Programs\Python\Python310\lib\site-packages\nbclient\client.py", line 918, in _check_raise_for_error
    raise CellExecutionError.from_cell_and_msg(cell, exec_reply_content)
nbclient.exceptions.CellExecutionError: An error occurred while executing the following cell:
------------------
def cp(nombre_archivo, nombre_copia):
    with open(nombre_archivo, 'rb') as archivo:
        contenido = archivo.read()

    with open(nombre_copia, 'wb') as archivo:
        archivo.write(contenido)

archivo = './sample_data/README.md'
copia = './copia.md'

cp(archivo, copia+'2')
------------------


[1;31m---------------------------------------------------------------------------[0m
[1;31mFileNotFoundError[0m                         Traceback (most recent call last)
Cell [1;32mIn[3], line 11[0m
[0;32m      8[0m archivo [38;5;241m=[39m [38;5;124m'[39m[38;5;124m./sample_data/README.md[39m[38;5;124m'[39m
[0;32m      9[0m copia [38;5;241m=[39m [38;5;124m'[39m[38;5;124m./copia.md[39m[38;5;124m'[39m
[1;32m---> 11[0m [43mcp[49m[43m([49m[43marchivo[49m[43m,[49m[43m [49m[43mcopia[49m[38;5;241;43m+[39;49m[38;5;124;43m'[39;49m[38;5;124;43m2[39;49m[38;5;124;43m'[39;49m[43m)[49m

Cell [1;32mIn[3], line 2[0m, in [0;36mcp[1;34m(nombre_archivo, nombre_copia)[0m
[0;32m      1[0m [38;5;28;01mdef[39;00m [38;5;21mcp[39m(nombre_archivo, nombre_copia):
[1;32m----> 2[0m     [38;5;28;01mwith[39;00m [38;5;28;43mopen[39;49m[43m([49m[43mnombre_archivo[49m[43m,[49m[43m [49m[38;5;124;43m'[39;49m[38;5;124;43mrb[39;49m[38;5;124;43m'[39;49m[43m)[49m [38;5;28;01mas[39;00m archivo:
[0;32m      3[0m         contenido [38;5;241m=[39m archivo[38;5;241m.[39mread()
[0;32m      5[0m     [38;5;28;01mwith[39;00m [38;5;28mopen[39m(nombre_copia, [38;5;124m'[39m[38;5;124mwb[39m[38;5;124m'[39m) [38;5;28;01mas[39;00m archivo:

File [1;32m~\AppData\Roaming\Python\Python310\site-packages\IPython\core\interactiveshell.py:310[0m, in [0;36m_modified_open[1;34m(file, *args, **kwargs)[0m
[0;32m    303[0m [38;5;28;01mif[39;00m file [38;5;129;01min[39;00m {[38;5;241m0[39m, [38;5;241m1[39m, [38;5;241m2[39m}:
[0;32m    304[0m     [38;5;28;01mraise[39;00m [38;5;167;01mValueError[39;00m(
[0;32m    305[0m         [38;5;124mf[39m[38;5;124m"[39m[38;5;124mIPython won[39m[38;5;124m'[39m[38;5;124mt let you open fd=[39m[38;5;132;01m{[39;00mfile[38;5;132;01m}[39;00m[38;5;124m by default [39m[38;5;124m"[39m
[0;32m    306[0m         [38;5;124m"[39m[38;5;124mas it is likely to crash IPython. If you know what you are doing, [39m[38;5;124m"[39m
[0;32m    307[0m         [38;5;124m"[39m[38;5;124myou can use builtins[39m[38;5;124m'[39m[38;5;124m open.[39m[38;5;124m"[39m
[0;32m    308[0m     )
[1;32m--> 310[0m [38;5;28;01mreturn[39;00m io_open(file, [38;5;241m*[39margs, [38;5;241m*[39m[38;5;241m*[39mkwargs)

[1;31mFileNotFoundError[0m: [Errno 2] No such file or directory: './sample_data/README.md'

