Traceback (most recent call last):
  File "C:\Users\tirab\Documents\GitHub\Algoritmos-y-Programacion\envs\ayp\lib\site-packages\jupyter_cache\executors\utils.py", line 58, in single_nb_execution
    executenb(
  File "C:\Users\tirab\Documents\GitHub\Algoritmos-y-Programacion\envs\ayp\lib\site-packages\nbclient\client.py", line 1314, in execute
    return NotebookClient(nb=nb, resources=resources, km=km, **kwargs).execute()
  File "C:\Users\tirab\Documents\GitHub\Algoritmos-y-Programacion\envs\ayp\lib\site-packages\jupyter_core\utils\__init__.py", line 165, in wrapped
    return loop.run_until_complete(inner)
  File "C:\Users\tirab\AppData\Local\Programs\Python\Python39\lib\asyncio\base_events.py", line 642, in run_until_complete
    return future.result()
  File "C:\Users\tirab\Documents\GitHub\Algoritmos-y-Programacion\envs\ayp\lib\site-packages\nbclient\client.py", line 709, in async_execute
    await self.async_execute_cell(
  File "C:\Users\tirab\Documents\GitHub\Algoritmos-y-Programacion\envs\ayp\lib\site-packages\nbclient\client.py", line 1062, in async_execute_cell
    await self._check_raise_for_error(cell, cell_index, exec_reply)
  File "C:\Users\tirab\Documents\GitHub\Algoritmos-y-Programacion\envs\ayp\lib\site-packages\nbclient\client.py", line 918, in _check_raise_for_error
    raise CellExecutionError.from_cell_and_msg(cell, exec_reply_content)
nbclient.exceptions.CellExecutionError: An error occurred while executing the following cell:
------------------
# Esta celda de cÃ³digo es para cargar el archivo en "Archivos" de este cuaderno.
# No hace falta si estamos trabajando en nuestra computadora y el archivo se encuentra localmente
import requests
archivos = ['Ascochinga_MTB.gpx', 'Punilla_MTB.gpx', 'Punilla_Observatorio.gpx']
for archivo in archivos:
    url = 'https://raw.githubusercontent.com/tirabo/Algoritmos-y-Programacion/main/2023/archivos/' + archivo
    response = requests.get(url)

    if response.status_code == 200:
        datos = response.text # datos es una str
        with open('/content/' + archivo, 'w') as f:
            f.write(datos)
    else:
        print('Hubo un problema al cargar el archivo')

------------------


[1;31m---------------------------------------------------------------------------[0m
[1;31mFileNotFoundError[0m                         Traceback (most recent call last)
Cell [1;32mIn[1], line 11[0m
[0;32m      9[0m [38;5;28;01mif[39;00m response[38;5;241m.[39mstatus_code [38;5;241m==[39m [38;5;241m200[39m:
[0;32m     10[0m     datos [38;5;241m=[39m response[38;5;241m.[39mtext [38;5;66;03m# datos es una str[39;00m
[1;32m---> 11[0m     [38;5;28;01mwith[39;00m [38;5;28;43mopen[39;49m[43m([49m[38;5;124;43m'[39;49m[38;5;124;43m/content/[39;49m[38;5;124;43m'[39;49m[43m [49m[38;5;241;43m+[39;49m[43m [49m[43marchivo[49m[43m,[49m[43m [49m[38;5;124;43m'[39;49m[38;5;124;43mw[39;49m[38;5;124;43m'[39;49m[43m)[49m [38;5;28;01mas[39;00m f:
[0;32m     12[0m         f[38;5;241m.[39mwrite(datos)
[0;32m     13[0m [38;5;28;01melse[39;00m:

File [1;32m~\Documents\GitHub\Algoritmos-y-Programacion\envs\ayp\lib\site-packages\IPython\core\interactiveshell.py:310[0m, in [0;36m_modified_open[1;34m(file, *args, **kwargs)[0m
[0;32m    303[0m [38;5;28;01mif[39;00m file [38;5;129;01min[39;00m {[38;5;241m0[39m, [38;5;241m1[39m, [38;5;241m2[39m}:
[0;32m    304[0m     [38;5;28;01mraise[39;00m [38;5;167;01mValueError[39;00m(
[0;32m    305[0m         [38;5;124mf[39m[38;5;124m"[39m[38;5;124mIPython won[39m[38;5;124m'[39m[38;5;124mt let you open fd=[39m[38;5;132;01m{[39;00mfile[38;5;132;01m}[39;00m[38;5;124m by default [39m[38;5;124m"[39m
[0;32m    306[0m         [38;5;124m"[39m[38;5;124mas it is likely to crash IPython. If you know what you are doing, [39m[38;5;124m"[39m
[0;32m    307[0m         [38;5;124m"[39m[38;5;124myou can use builtins[39m[38;5;124m'[39m[38;5;124m open.[39m[38;5;124m"[39m
[0;32m    308[0m     )
[1;32m--> 310[0m [38;5;28;01mreturn[39;00m io_open(file, [38;5;241m*[39margs, [38;5;241m*[39m[38;5;241m*[39mkwargs)

[1;31mFileNotFoundError[0m: [Errno 2] No such file or directory: '/content/Ascochinga_MTB.gpx'

