Traceback (most recent call last):
  File "C:\Users\tirab\AppData\Local\Programs\Python\Python310\lib\site-packages\nbclient\client.py", line 782, in _async_poll_for_reply
    msg = await ensure_async(self.kc.shell_channel.get_msg(timeout=new_timeout))
  File "C:\Users\tirab\AppData\Roaming\Python\Python310\site-packages\jupyter_core\utils\__init__.py", line 189, in ensure_async
    result = await obj
  File "C:\Users\tirab\AppData\Roaming\Python\Python310\site-packages\jupyter_client\channels.py", line 315, in get_msg
    raise Empty
_queue.Empty

During handling of the above exception, another exception occurred:

Traceback (most recent call last):
  File "C:\Users\tirab\AppData\Local\Programs\Python\Python310\lib\site-packages\jupyter_cache\executors\utils.py", line 58, in single_nb_execution
    executenb(
  File "C:\Users\tirab\AppData\Local\Programs\Python\Python310\lib\site-packages\nbclient\client.py", line 1314, in execute
    return NotebookClient(nb=nb, resources=resources, km=km, **kwargs).execute()
  File "C:\Users\tirab\AppData\Roaming\Python\Python310\site-packages\jupyter_core\utils\__init__.py", line 173, in wrapped
    return loop.run_until_complete(inner)
  File "C:\Users\tirab\AppData\Local\Programs\Python\Python310\lib\asyncio\base_events.py", line 646, in run_until_complete
    return future.result()
  File "C:\Users\tirab\AppData\Local\Programs\Python\Python310\lib\site-packages\nbclient\client.py", line 709, in async_execute
    await self.async_execute_cell(
  File "C:\Users\tirab\AppData\Local\Programs\Python\Python310\lib\site-packages\nbclient\client.py", line 1005, in async_execute_cell
    exec_reply = await self.task_poll_for_reply
  File "C:\Users\tirab\AppData\Local\Programs\Python\Python310\lib\site-packages\nbclient\client.py", line 806, in _async_poll_for_reply
    error_on_timeout_execute_reply = await self._async_handle_timeout(timeout, cell)
  File "C:\Users\tirab\AppData\Local\Programs\Python\Python310\lib\site-packages\nbclient\client.py", line 856, in _async_handle_timeout
    raise CellTimeoutError.error_from_timeout_and_cell(
nbclient.exceptions.CellTimeoutError: A cell timed out while it was being executed, after 30 seconds.
The message was: Cell execution timed out.
Here is a preview of the cell contents:
-------------------
pizarra_vacia(velocidad=10)
for x in range(10):
    for y in range(10):
        penup()
        goto(-300 + x*60, 150 - y*30)
        pendown()
        dibujar_rectangulo(60, 30)


# exitonclick()

-------------------

